<?xml version="1.0"?>
<!-- Auto-generated by isaac_sim/scripts/generate_urdf.py -->
<!-- Dual SO-101 (SO-100) bimanual robot, prepared for Isaac Sim. -->
<robot name="so_100_dual">
  <link name="world"/>

  <!-- ============== LEFT ARM ============== -->
  <link name="left_base_link"/>
  <joint name="world_to_left_base" type="fixed">
    <origin xyz="-0.3 0 0" rpy="0 0 0"/>
    <parent link="world"/>
    <child link="left_base_link"/>
  </joint>
  <joint name="left_base_link_joint" type="fixed">
    <origin xyz="0 0 0" rpy="0 0 0"/>
    <parent link="left_base_link"/>
    <child link="left_Base"/>
  </joint>
  <link name="left_Base">
    <inertial>
      <origin xyz="-2.45961e-07 0.0311418 0.0175747" rpy="0 0 0"/>
      <mass value="0.193184"/>
      <inertia ixx="0.000137031" ixy="2.10136e-08" ixz="4.24087e-09" iyy="0.00016909" iyz="2.26515e-05" izz="0.000145098"/>
    </inertial>
    <visual>
      <origin xyz="0 0 0" rpy="0 0 0"/>
      <geometry><mesh filename="../../src/SO-100-arm/models/so_100_arm_5dof/meshes/Base.STL"/></geometry>
      <material name="so101_grey"><color rgba="0.79 0.82 0.93 1"/></material>
    </visual>
    <collision>
      <origin xyz="0 0 0" rpy="0 0 0"/>
      <geometry><mesh filename="../../src/SO-100-arm/models/so_100_arm_5dof/meshes/Base.STL"/></geometry>
    </collision>
  </link>
  <link name="left_Shoulder_Rotation_Pitch">
    <inertial>
      <origin xyz="-9.07886e-05 0.0590972 0.031089" rpy="0 0 0"/>
      <mass value="0.119226"/>
      <inertia ixx="5.90409e-05" ixy="4.90801e-07" ixz="-5.90452e-08" iyy="3.21499e-05" iyz="-4.58026e-06" izz="5.86059e-05"/>
    </inertial>
    <visual>
      <origin xyz="0 0 0" rpy="0 0 0"/>
      <geometry><mesh filename="../../src/SO-100-arm/models/so_100_arm_5dof/meshes/Shoulder_Rotation_Pitch.STL"/></geometry>
      <material name="so101_grey"><color rgba="0.79 0.82 0.93 1"/></material>
    </visual>
    <collision>
      <origin xyz="0 0 0" rpy="0 0 0"/>
      <geometry><mesh filename="../../src/SO-100-arm/models/so_100_arm_5dof/meshes/Shoulder_Rotation_Pitch.STL"/></geometry>
    </collision>
  </link>
  <link name="left_Upper_Arm">
    <inertial>
      <origin xyz="-1.72052e-05 0.0701802 0.00310545" rpy="0 0 0"/>
      <mass value="0.162409"/>
      <inertia ixx="0.000167153" ixy="1.03903e-06" ixz="-1.20162e-08" iyy="7.01947e-05" iyz="2.11885e-06" izz="0.00021328"/>
    </inertial>
    <visual>
      <origin xyz="0 0 0" rpy="0 0 0"/>
      <geometry><mesh filename="../../src/SO-100-arm/models/so_100_arm_5dof/meshes/Upper_Arm.STL"/></geometry>
      <material name="so101_grey"><color rgba="0.79 0.82 0.93 1"/></material>
    </visual>
    <collision>
      <origin xyz="0 0 0" rpy="0 0 0"/>
      <geometry><mesh filename="../../src/SO-100-arm/models/so_100_arm_5dof/meshes/Upper_Arm.STL"/></geometry>
    </collision>
  </link>
  <link name="left_Lower_Arm">
    <inertial>
      <origin xyz="-0.00339604 0.00137796 0.0768007" rpy="0 0 0"/>
      <mass value="0.147968"/>
      <inertia ixx="0.000105334" ixy="1.73059e-07" ixz="-1.17203e-05" iyy="0.000138767" iyz="1.7743e-06" izz="5.08742e-05"/>
    </inertial>
    <visual>
      <origin xyz="0 0 0" rpy="0 0 0"/>
      <geometry><mesh filename="../../src/SO-100-arm/models/so_100_arm_5dof/meshes/Lower_Arm.STL"/></geometry>
      <material name="so101_grey"><color rgba="0.79 0.82 0.93 1"/></material>
    </visual>
    <collision>
      <origin xyz="0 0 0" rpy="0 0 0"/>
      <geometry><mesh filename="../../src/SO-100-arm/models/so_100_arm_5dof/meshes/Lower_Arm.STL"/></geometry>
    </collision>
  </link>
  <link name="left_Wrist_Pitch_Roll">
    <inertial>
      <origin xyz="-0.00852653 -0.0352279 -2.34622e-05" rpy="0 0 0"/>
      <mass value="0.0661321"/>
      <inertia ixx="1.95717e-05" ixy="-6.62714e-07" ixz="5.20089e-09" iyy="2.38028e-05" iyz="4.09549e-08" izz="3.45401e-05"/>
    </inertial>
    <visual>
      <origin xyz="0 0 0" rpy="0 0 0"/>
      <geometry><mesh filename="../../src/SO-100-arm/models/so_100_arm_5dof/meshes/Wrist_Pitch_Roll.STL"/></geometry>
      <material name="so101_grey"><color rgba="0.79 0.82 0.93 1"/></material>
    </visual>
    <collision>
      <origin xyz="0 0 0" rpy="0 0 0"/>
      <geometry><mesh filename="../../src/SO-100-arm/models/so_100_arm_5dof/meshes/Wrist_Pitch_Roll.STL"/></geometry>
    </collision>
  </link>
  <link name="left_Fixed_Gripper">
    <inertial>
      <origin xyz="0.00552377 -0.0280167 0.000483583" rpy="0 0 0"/>
      <mass value="0.0929859"/>
      <inertia ixx="4.33282e-05" ixy="7.09654e-06" ixz="5.99839e-07" iyy="3.04452e-05" iyz="-1.58743e-07" izz="5.02461e-05"/>
    </inertial>
    <visual>
      <origin xyz="0 0 0" rpy="0 0 0"/>
      <geometry><mesh filename="../../src/SO-100-arm/models/so_100_arm_5dof/meshes/Fixed_Gripper.STL"/></geometry>
      <material name="so101_grey"><color rgba="0.79 0.82 0.93 1"/></material>
    </visual>
    <collision>
      <origin xyz="0 0 0" rpy="0 0 0"/>
      <geometry><mesh filename="../../src/SO-100-arm/models/so_100_arm_5dof/meshes/Fixed_Gripper.STL"/></geometry>
    </collision>
  </link>
  <link name="left_Moving_Jaw">
    <inertial>
      <origin xyz="-0.00161745 -0.0303473 0.000449646" rpy="0 0 0"/>
      <mass value="0.0202444"/>
      <inertia ixx="1.10911e-05" ixy="-5.35077e-07" ixz="-9.46106e-09" iyy="3.03576e-06" iyz="-1.71146e-07" izz="8.99161e-06"/>
    </inertial>
    <visual>
      <origin xyz="0 0 0" rpy="0 0 0"/>
      <geometry><mesh filename="../../src/SO-100-arm/models/so_100_arm_5dof/meshes/Moving_Jaw.STL"/></geometry>
      <material name="so101_grey"><color rgba="0.79 0.82 0.93 1"/></material>
    </visual>
    <collision>
      <origin xyz="0 0 0" rpy="0 0 0"/>
      <geometry><mesh filename="../../src/SO-100-arm/models/so_100_arm_5dof/meshes/Moving_Jaw.STL"/></geometry>
    </collision>
  </link>
  <joint name="left_Shoulder_Rotation" type="revolute">
    <origin xyz="0 -0.0452 0.0165" rpy="1.5708 0 0"/>
    <parent link="left_Base"/>
    <child link="left_Shoulder_Rotation_Pitch"/>
    <axis xyz="0 1 0"/>
    <limit lower="-3.3" upper="3.3" effort="5" velocity="2"/>
  </joint>
  <joint name="left_Shoulder_Pitch" type="revolute">
    <origin xyz="0 0.1025 0.0306" rpy="0 0 0"/>
    <parent link="left_Shoulder_Rotation_Pitch"/>
    <child link="left_Upper_Arm"/>
    <axis xyz="1 0 0"/>
    <limit lower="-3.14159" upper="3.14159" effort="5" velocity="2"/>
  </joint>
  <joint name="left_Elbow" type="revolute">
    <origin xyz="0 0.11257 0.028" rpy="0 0 0"/>
    <parent link="left_Upper_Arm"/>
    <child link="left_Lower_Arm"/>
    <axis xyz="1 0 0"/>
    <limit lower="-3.14159" upper="3.14159" effort="5" velocity="2"/>
  </joint>
  <joint name="left_Wrist_Pitch" type="revolute">
    <origin xyz="0 0.0052 0.1349" rpy="0 0 0"/>
    <parent link="left_Lower_Arm"/>
    <child link="left_Wrist_Pitch_Roll"/>
    <axis xyz="1 0 0"/>
    <limit lower="-3.14159" upper="3.14159" effort="5" velocity="2"/>
  </joint>
  <joint name="left_Wrist_Roll" type="revolute">
    <origin xyz="0 -0.0601 0" rpy="0 0 0"/>
    <parent link="left_Wrist_Pitch_Roll"/>
    <child link="left_Fixed_Gripper"/>
    <axis xyz="0 1 0"/>
    <limit lower="-3.14159" upper="3.14159" effort="5" velocity="2"/>
  </joint>
  <joint name="left_Gripper" type="revolute">
    <origin xyz="-0.0202 -0.0244 0" rpy="3.1416 0 3.1416"/>
    <parent link="left_Fixed_Gripper"/>
    <child link="left_Moving_Jaw"/>
    <axis xyz="0 0 1"/>
    <limit lower="-0.2" upper="1.7" effort="5" velocity="2"/>
  </joint>

  <!-- ============== RIGHT ARM ============== -->
  <link name="right_base_link"/>
  <joint name="world_to_right_base" type="fixed">
    <origin xyz="0.3 0 0" rpy="0 0 0"/>
    <parent link="world"/>
    <child link="right_base_link"/>
  </joint>
  <joint name="right_base_link_joint" type="fixed">
    <origin xyz="0 0 0" rpy="0 0 0"/>
    <parent link="right_base_link"/>
    <child link="right_Base"/>
  </joint>
  <link name="right_Base">
    <inertial>
      <origin xyz="-2.45961e-07 0.0311418 0.0175747" rpy="0 0 0"/>
      <mass value="0.193184"/>
      <inertia ixx="0.000137031" ixy="2.10136e-08" ixz="4.24087e-09" iyy="0.00016909" iyz="2.26515e-05" izz="0.000145098"/>
    </inertial>
    <visual>
      <origin xyz="0 0 0" rpy="0 0 0"/>
      <geometry><mesh filename="../../src/SO-100-arm/models/so_100_arm_5dof/meshes/Base.STL"/></geometry>
      <material name="so101_grey"><color rgba="0.79 0.82 0.93 1"/></material>
    </visual>
    <collision>
      <origin xyz="0 0 0" rpy="0 0 0"/>
      <geometry><mesh filename="../../src/SO-100-arm/models/so_100_arm_5dof/meshes/Base.STL"/></geometry>
    </collision>
  </link>
  <link name="right_Shoulder_Rotation_Pitch">
    <inertial>
      <origin xyz="-9.07886e-05 0.0590972 0.031089" rpy="0 0 0"/>
      <mass value="0.119226"/>
      <inertia ixx="5.90409e-05" ixy="4.90801e-07" ixz="-5.90452e-08" iyy="3.21499e-05" iyz="-4.58026e-06" izz="5.86059e-05"/>
    </inertial>
    <visual>
      <origin xyz="0 0 0" rpy="0 0 0"/>
      <geometry><mesh filename="../../src/SO-100-arm/models/so_100_arm_5dof/meshes/Shoulder_Rotation_Pitch.STL"/></geometry>
      <material name="so101_grey"><color rgba="0.79 0.82 0.93 1"/></material>
    </visual>
    <collision>
      <origin xyz="0 0 0" rpy="0 0 0"/>
      <geometry><mesh filename="../../src/SO-100-arm/models/so_100_arm_5dof/meshes/Shoulder_Rotation_Pitch.STL"/></geometry>
    </collision>
  </link>
  <link name="right_Upper_Arm">
    <inertial>
      <origin xyz="-1.72052e-05 0.0701802 0.00310545" rpy="0 0 0"/>
      <mass value="0.162409"/>
      <inertia ixx="0.000167153" ixy="1.03903e-06" ixz="-1.20162e-08" iyy="7.01947e-05" iyz="2.11885e-06" izz="0.00021328"/>
    </inertial>
    <visual>
      <origin xyz="0 0 0" rpy="0 0 0"/>
      <geometry><mesh filename="../../src/SO-100-arm/models/so_100_arm_5dof/meshes/Upper_Arm.STL"/></geometry>
      <material name="so101_grey"><color rgba="0.79 0.82 0.93 1"/></material>
    </visual>
    <collision>
      <origin xyz="0 0 0" rpy="0 0 0"/>
      <geometry><mesh filename="../../src/SO-100-arm/models/so_100_arm_5dof/meshes/Upper_Arm.STL"/></geometry>
    </collision>
  </link>
  <link name="right_Lower_Arm">
    <inertial>
      <origin xyz="-0.00339604 0.00137796 0.0768007" rpy="0 0 0"/>
      <mass value="0.147968"/>
      <inertia ixx="0.000105334" ixy="1.73059e-07" ixz="-1.17203e-05" iyy="0.000138767" iyz="1.7743e-06" izz="5.08742e-05"/>
    </inertial>
    <visual>
      <origin xyz="0 0 0" rpy="0 0 0"/>
      <geometry><mesh filename="../../src/SO-100-arm/models/so_100_arm_5dof/meshes/Lower_Arm.STL"/></geometry>
      <material name="so101_grey"><color rgba="0.79 0.82 0.93 1"/></material>
    </visual>
    <collision>
      <origin xyz="0 0 0" rpy="0 0 0"/>
      <geometry><mesh filename="../../src/SO-100-arm/models/so_100_arm_5dof/meshes/Lower_Arm.STL"/></geometry>
    </collision>
  </link>
  <link name="right_Wrist_Pitch_Roll">
    <inertial>
      <origin xyz="-0.00852653 -0.0352279 -2.34622e-05" rpy="0 0 0"/>
      <mass value="0.0661321"/>
      <inertia ixx="1.95717e-05" ixy="-6.62714e-07" ixz="5.20089e-09" iyy="2.38028e-05" iyz="4.09549e-08" izz="3.45401e-05"/>
    </inertial>
    <visual>
      <origin xyz="0 0 0" rpy="0 0 0"/>
      <geometry><mesh filename="../../src/SO-100-arm/models/so_100_arm_5dof/meshes/Wrist_Pitch_Roll.STL"/></geometry>
      <material name="so101_grey"><color rgba="0.79 0.82 0.93 1"/></material>
    </visual>
    <collision>
      <origin xyz="0 0 0" rpy="0 0 0"/>
      <geometry><mesh filename="../../src/SO-100-arm/models/so_100_arm_5dof/meshes/Wrist_Pitch_Roll.STL"/></geometry>
    </collision>
  </link>
  <link name="right_Fixed_Gripper">
    <inertial>
      <origin xyz="0.00552377 -0.0280167 0.000483583" rpy="0 0 0"/>
      <mass value="0.0929859"/>
      <inertia ixx="4.33282e-05" ixy="7.09654e-06" ixz="5.99839e-07" iyy="3.04452e-05" iyz="-1.58743e-07" izz="5.02461e-05"/>
    </inertial>
    <visual>
      <origin xyz="0 0 0" rpy="0 0 0"/>
      <geometry><mesh filename="../../src/SO-100-arm/models/so_100_arm_5dof/meshes/Fixed_Gripper.STL"/></geometry>
      <material name="so101_grey"><color rgba="0.79 0.82 0.93 1"/></material>
    </visual>
    <collision>
      <origin xyz="0 0 0" rpy="0 0 0"/>
      <geometry><mesh filename="../../src/SO-100-arm/models/so_100_arm_5dof/meshes/Fixed_Gripper.STL"/></geometry>
    </collision>
  </link>
  <link name="right_Moving_Jaw">
    <inertial>
      <origin xyz="-0.00161745 -0.0303473 0.000449646" rpy="0 0 0"/>
      <mass value="0.0202444"/>
      <inertia ixx="1.10911e-05" ixy="-5.35077e-07" ixz="-9.46106e-09" iyy="3.03576e-06" iyz="-1.71146e-07" izz="8.99161e-06"/>
    </inertial>
    <visual>
      <origin xyz="0 0 0" rpy="0 0 0"/>
      <geometry><mesh filename="../../src/SO-100-arm/models/so_100_arm_5dof/meshes/Moving_Jaw.STL"/></geometry>
      <material name="so101_grey"><color rgba="0.79 0.82 0.93 1"/></material>
    </visual>
    <collision>
      <origin xyz="0 0 0" rpy="0 0 0"/>
      <geometry><mesh filename="../../src/SO-100-arm/models/so_100_arm_5dof/meshes/Moving_Jaw.STL"/></geometry>
    </collision>
  </link>
  <joint name="right_Shoulder_Rotation" type="revolute">
    <origin xyz="0 -0.0452 0.0165" rpy="1.5708 0 0"/>
    <parent link="right_Base"/>
    <child link="right_Shoulder_Rotation_Pitch"/>
    <axis xyz="0 1 0"/>
    <limit lower="-3.3" upper="3.3" effort="5" velocity="2"/>
  </joint>
  <joint name="right_Shoulder_Pitch" type="revolute">
    <origin xyz="0 0.1025 0.0306" rpy="0 0 0"/>
    <parent link="right_Shoulder_Rotation_Pitch"/>
    <child link="right_Upper_Arm"/>
    <axis xyz="1 0 0"/>
    <limit lower="-3.14159" upper="3.14159" effort="5" velocity="2"/>
  </joint>
  <joint name="right_Elbow" type="revolute">
    <origin xyz="0 0.11257 0.028" rpy="0 0 0"/>
    <parent link="right_Upper_Arm"/>
    <child link="right_Lower_Arm"/>
    <axis xyz="1 0 0"/>
    <limit lower="-3.14159" upper="3.14159" effort="5" velocity="2"/>
  </joint>
  <joint name="right_Wrist_Pitch" type="revolute">
    <origin xyz="0 0.0052 0.1349" rpy="0 0 0"/>
    <parent link="right_Lower_Arm"/>
    <child link="right_Wrist_Pitch_Roll"/>
    <axis xyz="1 0 0"/>
    <limit lower="-3.14159" upper="3.14159" effort="5" velocity="2"/>
  </joint>
  <joint name="right_Wrist_Roll" type="revolute">
    <origin xyz="0 -0.0601 0" rpy="0 0 0"/>
    <parent link="right_Wrist_Pitch_Roll"/>
    <child link="right_Fixed_Gripper"/>
    <axis xyz="0 1 0"/>
    <limit lower="-3.14159" upper="3.14159" effort="5" velocity="2"/>
  </joint>
  <joint name="right_Gripper" type="revolute">
    <origin xyz="-0.0202 -0.0244 0" rpy="3.1416 0 3.1416"/>
    <parent link="right_Fixed_Gripper"/>
    <child link="right_Moving_Jaw"/>
    <axis xyz="0 0 1"/>
    <limit lower="-0.2" upper="1.7" effort="5" velocity="2"/>
  </joint>
</robot>
